Traceback (most recent call last):
  File "/home/pbellec/env/editorial_parcellation/lib/python3.8/site-packages/jupyter_cache/executors/utils.py", line 51, in single_nb_execution
    executenb(
  File "/home/pbellec/env/editorial_parcellation/lib/python3.8/site-packages/nbclient/client.py", line 1117, in execute
    return NotebookClient(nb=nb, resources=resources, km=km, **kwargs).execute()
  File "/home/pbellec/env/editorial_parcellation/lib/python3.8/site-packages/nbclient/util.py", line 78, in wrapped
    return just_run(coro(*args, **kwargs))
  File "/home/pbellec/env/editorial_parcellation/lib/python3.8/site-packages/nbclient/util.py", line 57, in just_run
    return loop.run_until_complete(coro)
  File "/usr/lib/python3.8/asyncio/base_events.py", line 616, in run_until_complete
    return future.result()
  File "/home/pbellec/env/editorial_parcellation/lib/python3.8/site-packages/nbclient/client.py", line 558, in async_execute
    await self.async_execute_cell(
  File "/home/pbellec/env/editorial_parcellation/lib/python3.8/site-packages/nbclient/client.py", line 862, in async_execute_cell
    self._check_raise_for_error(cell, exec_reply)
  File "/home/pbellec/env/editorial_parcellation/lib/python3.8/site-packages/nbclient/client.py", line 765, in _check_raise_for_error
    raise CellExecutionError.from_cell_and_msg(cell, exec_reply_content)
nbclient.exceptions.CellExecutionError: An error occurred while executing the following cell:
------------------
import urllib.request
import pandas as pd
import os
data = pd.read_csv(os.path.join(path_data, '9843721'), sep='\t',header=0)
# Show us the data!
pd.set_option("max_rows", 5)
data
------------------

[0;31m---------------------------------------------------------------------------[0m
[0;31mTypeError[0m                                 Traceback (most recent call last)
[0;32m/tmp/ipykernel_9015/2150805816.py[0m in [0;36m<module>[0;34m[0m
[1;32m      2[0m [0;32mimport[0m [0mpandas[0m [0;32mas[0m [0mpd[0m[0;34m[0m[0;34m[0m[0m
[1;32m      3[0m [0;32mimport[0m [0mos[0m[0;34m[0m[0;34m[0m[0m
[0;32m----> 4[0;31m [0mdata[0m [0;34m=[0m [0mpd[0m[0;34m.[0m[0mread_csv[0m[0;34m([0m[0mos[0m[0;34m.[0m[0mpath[0m[0;34m.[0m[0mjoin[0m[0;34m([0m[0mpath_data[0m[0;34m,[0m [0;34m'9843721'[0m[0;34m)[0m[0;34m,[0m [0msep[0m[0;34m=[0m[0;34m'\t'[0m[0;34m,[0m[0mheader[0m[0;34m=[0m[0;36m0[0m[0;34m)[0m[0;34m[0m[0;34m[0m[0m
[0m[1;32m      5[0m [0;31m# Show us the data![0m[0;34m[0m[0;34m[0m[0;34m[0m[0m
[1;32m      6[0m [0mpd[0m[0;34m.[0m[0mset_option[0m[0;34m([0m[0;34m"max_rows"[0m[0;34m,[0m [0;36m5[0m[0;34m)[0m[0;34m[0m[0;34m[0m[0m

[0;32m/usr/lib/python3.8/posixpath.py[0m in [0;36mjoin[0;34m(a, *p)[0m
[1;32m     74[0m     [0mwill[0m [0mbe[0m [0mdiscarded[0m[0;34m.[0m  [0mAn[0m [0mempty[0m [0mlast[0m [0mpart[0m [0mwill[0m [0mresult[0m [0;32min[0m [0ma[0m [0mpath[0m [0mthat[0m[0;34m[0m[0;34m[0m[0m
[1;32m     75[0m     ends with a separator."""
[0;32m---> 76[0;31m     [0ma[0m [0;34m=[0m [0mos[0m[0;34m.[0m[0mfspath[0m[0;34m([0m[0ma[0m[0;34m)[0m[0;34m[0m[0;34m[0m[0m
[0m[1;32m     77[0m     [0msep[0m [0;34m=[0m [0m_get_sep[0m[0;34m([0m[0ma[0m[0;34m)[0m[0;34m[0m[0;34m[0m[0m
[1;32m     78[0m     [0mpath[0m [0;34m=[0m [0ma[0m[0;34m[0m[0;34m[0m[0m

[0;31mTypeError[0m: expected str, bytes or os.PathLike object, not list
TypeError: expected str, bytes or os.PathLike object, not list

